<?xml version="1.0" encoding="utf-8"?>
<!-- This URDF was automatically created by SolidWorks to URDF Exporter! Originally created by Stephen Brawner (brawner@gmail.com) 
     Commit Version: 1.5.1-0-g916b5db  Build Version: 1.5.7152.31018
     For more information, please see http://wiki.ros.org/sw_urdf_exporter -->

<robot name="scholar" xmlns:xacro="http://ros.org/wiki/xacro">

  <xacro:arg name="robot_namespace" default="/" />  
  <xacro:property name="wheel_length" value="0.07" />
  <xacro:property name="wheel_radius" value="0.1325" />

  <link
    name="base_link">
    <inertial>
      <origin
        xyz="-0.0031619 0.0009625 0.097176"
        rpy="0 0 0" />
      <mass
        value="39.45" />
      <inertia
        ixx="0.3395"
        ixy="0.0034895"
        ixz="0.0083273"
        iyy="0.53446"
        iyz="-0.0007813"
        izz="0.70987" />
    </inertial>
    <visual>
      <origin
        xyz="0 0 0"
        rpy="0 0 0" />
      <geometry>
        <mesh
          filename="package://scholar_description/meshes/base_link.STL" />
      </geometry>
      <material
        name="">
        <color
          rgba="0 0 0.62745 1" />
      </material>
    </visual>
    <collision>
      <origin
        xyz="0 0 0"
        rpy="0 0 0" />
      <geometry>
        <mesh
          filename="package://scholar_description/meshes/base_link.STL" />
      </geometry>
    </collision>
  </link>
  <link
    name="top_plate_link">
    <inertial>
      <origin
        xyz="-0.0076076 5.5875E-06 0.0024988"
        rpy="0 0 0" />
      <mass
        value="3.5537" />
      <inertia
        ixx="0.071514"
        ixy="-7.6821E-06"
        ixz="-4.2935E-07"
        iyy="0.095212"
        iyz="-2.4655E-11"
        izz="0.16671" />
    </inertial>
    <visual>
      <origin
        xyz="0 0 0"
        rpy="0 0 0" />
      <geometry>
        <mesh
          filename="package://scholar_description/meshes/top_plate_link.STL" />
      </geometry>
      <material
        name="">
        <color
          rgba="0.89804 0.91765 0.92941 1" />
      </material>
    </visual>
    <collision>
      <origin
        xyz="0 0 0"
        rpy="0 0 0" />
      <geometry>
        <mesh
          filename="package://scholar_description/meshes/top_plate_link.STL" />
      </geometry>
    </collision>
  </link>
  <joint
    name="top_plate_base_joint"
    type="fixed">
    <origin
      xyz="0.062403 -0.0010246 0.23019"
      rpy="0 0 0" />
    <parent
      link="base_link" />
    <child
      link="top_plate_link" />
    <axis
      xyz="0 0 0" />
  </joint>
  


  <xacro:if value="$(arg laser_enabled)">



<link
    name="base_laser">
    <inertial>
      <origin
        xyz="-0.00029774 0.0066667 0.00013047"
        rpy="0 0 0" />
      <mass
        value="0.15717" />
      <inertia
        ixx="6.7885E-05"
        ixy="-1.3987E-07"
        ixz="-8.1554E-07"
        iyy="0.00013173"
        iyz="-9.0932E-08"
        izz="7.1972E-05" />
    </inertial>
    <visual>
      <origin
        xyz="0 0 0"
        rpy="0 0 0" />
      <geometry>
        <mesh
          filename="package://scholar_description/meshes/ydlidar.dae" />
      </geometry>
      <material
        name="">
        <color
          rgba="0.64706 0.61961 0.58824 1" />
      </material>
    </visual>
    <collision>
      <origin
        xyz="0 0 0"
        rpy="0 0 0" />
      <geometry>
        <mesh
          filename="package://scholar_description/meshes/ydlidar.dae" />
      </geometry>
    </collision>
  </link>

  <link
    name="laser_frame">
    <inertial>
      <origin
        xyz="-0.00036659 0.00064155 -0.00027052"
        rpy="0 0 0" />
      <mass
        value="0.25482" />
      <inertia
        ixx="8.9194E-05"
        ixy="1.8116E-07"
        ixz="3.6435E-08"
        iyy="0.00018279"
        iyz="2.423E-07"
        izz="0.00011103" />
    </inertial>   
  </link>
  <joint
    name="laser_joint"
    type="fixed">
    <origin
      xyz="0 0 0.03172"
      rpy="0 0 0" />
    <parent
      link="base_laser" />
    <child
      link="laser_frame" />
    <axis
      xyz="0 0 0" />
  </joint>

 <joint
    name="laser_to_top_plate_joint"
    type="fixed">
    <origin
      xyz="0.24503 0 0"
      rpy="3.1416 0 0" />
    <parent
      link="top_plate_link" />
    <child
      link="base_laser" />
    <axis
      xyz="0 0 0" />
  </joint>

  </xacro:if>



  <link
    name="imu_link">    
  </link>
  <joint
    name="imu_joint"
    type="fixed">
    <origin
      xyz="0.2055 -0.008 0.0116"
      rpy="0 0 3.1416" />
    <parent
      link="base_link" />
    <child
      link="imu_link" />
    <axis
      xyz="0 0 0" />
  </joint>
  <link
    name="left_front_wheel_link">
    <inertial>
      <origin
        xyz="0 -0.00037977 0"
        rpy="0 0 0" />
      <mass
        value="2.856" />
      <inertia
        ixx="0.016151"
        ixy="-4.2683E-19"
        ixz="-1.4469E-33"
        iyy="0.029635"
        iyz="2.9972E-32"
        izz="0.016151" />
    </inertial>
    <visual>
      <origin
        xyz="0 0 0"
        rpy="0 0 0" />
      <geometry>
        <mesh
          filename="package://scholar_description/meshes/left_front_wheel_link.STL" />
      </geometry>
      <material
        name="">
        <color
          rgba="1 1 1 1" />
      </material>
    </visual>
    <collision>
      <origin
        xyz="0 0 0"
        rpy="1.5708 0 0" />
     <geometry>
	<cylinder length="${wheel_length}" radius="${wheel_radius}" />
     </geometry>
    </collision>
  </link>
  <joint
    name="left_front_wheel_joint"
    type="continuous">
    <origin
      xyz="0.199 0.2395 0.06"
      rpy="0 0 0" />
    <parent
      link="base_link" />
    <child
      link="left_front_wheel_link" />
    <axis
      xyz="0 1 0" />  
   
  </joint>


  <gazebo reference="left_front_wheel_link">
        <mu1 value="1.0"/>
        <mu2 value="1.0"/>
	<kp value="10000000.0" />
	<kd value="1.0" />
	<fdir1 value="1 0 0"/>
  </gazebo>

  <transmission name="left_front_wheel_trans" type="SimpleTransmission">
	<type>transmission_interface/SimpleTransmission</type>
	<actuator name="left_front_wheel_motor">
		<mechanicalReduction>1</mechanicalReduction>
	</actuator>
	<joint name="left_front_wheel_joint">
		<hardwareInterface>hardware_interface/VelocityJointInterface</hardwareInterface>
	</joint>
  </transmission>



  <link
    name="left_rear_wheel_link">
    <inertial>
      <origin
        xyz="-1.1102E-16 -0.00037977 -6.9389E-18"
        rpy="0 0 0" />
      <mass
        value="2.856" />
      <inertia
        ixx="0.016151"
        ixy="7.155E-19"
        ixz="-4.9304E-32"
        iyy="0.029635"
        iyz="-5.6105E-33"
        izz="0.016151" />
    </inertial>
    <visual>
      <origin
        xyz="0 0 0"
        rpy="0 0 0" />
      <geometry>
        <mesh
          filename="package://scholar_description/meshes/left_rear_wheel_link.STL" />
      </geometry>
      <material
        name="">
        <color
          rgba="1 1 1 1" />
      </material>
    </visual>
    <collision>
      <origin
        xyz="0 0 0"
        rpy="1.5708 0 0" />
      <geometry>
	<cylinder length="${wheel_length}" radius="${wheel_radius}" />
     </geometry>
    </collision>
  </link>
  <joint
    name="left_rear_wheel_joint"
    type="continuous">
    <origin
      xyz="-0.199 0.2395 0.06"
      rpy="0 0 0" />
    <parent
      link="base_link" />
    <child
      link="left_rear_wheel_link" />
    <axis
      xyz="0 1 0" />    
  </joint>


  <gazebo reference="left_rear_wheel_link">
        <mu1 value="1.0"/>
        <mu2 value="1.0"/>
	<kp value="10000000.0" />
	<kd value="1.0" />
	<fdir1 value="1 0 0"/>
  </gazebo>

  <transmission name="left_rear_wheel_trans" type="SimpleTransmission">
	<type>transmission_interface/SimpleTransmission</type>
	<actuator name="left_rear_wheel_motor">
		<mechanicalReduction>1</mechanicalReduction>
	</actuator>
	<joint name="left_rear_wheel_joint">
		<hardwareInterface>hardware_interface/VelocityJointInterface</hardwareInterface>
	</joint>
  </transmission>

  <link
    name="right_front_wheel_link">
    <inertial>
      <origin
        xyz="-1.7764E-15 0.00037977 -5.0515E-15"
        rpy="0 0 0" />
      <mass
        value="2.856" />
      <inertia
        ixx="0.016151"
        ixy="-1.4109E-16"
        ixz="-1.1075E-35"
        iyy="0.029635"
        iyz="-9.0278E-35"
        izz="0.016151" />
    </inertial>
    <visual>
      <origin
        xyz="0 0 0"
        rpy="0 0 0" />
      <geometry>
        <mesh
          filename="package://scholar_description/meshes/right_front_wheel_link.STL" />
      </geometry>
      <material
        name="">
        <color
          rgba="1 1 1 1" />
      </material>
    </visual>
    <collision>
      <origin
        xyz="0 0 0"
        rpy="1.5708 0 0" />
     <geometry>
	<cylinder length="${wheel_length}" radius="${wheel_radius}" />
     </geometry>
    </collision>
  </link>
  <joint
    name="right_front_wheel_joint"
    type="continuous">
    <origin
      xyz="0.199 -0.2395 0.06"
      rpy="0 0 0" />
    <parent
      link="base_link" />
    <child
      link="right_front_wheel_link" />
    <axis
      xyz="0 1 0" />    
  </joint>


  <gazebo reference="right_front_wheel_link">
        <mu1 value="1.0"/>
        <mu2 value="1.0"/>
	<kp value="10000000.0" />
	<kd value="1.0" />
	<fdir1 value="1 0 0"/>
  </gazebo>

  <transmission name="right_front_wheel_trans" type="SimpleTransmission">
	<type>transmission_interface/SimpleTransmission</type>
	<actuator name="right_front_wheel_motor">
		<mechanicalReduction>1</mechanicalReduction>
	</actuator>
	<joint name="right_front_wheel_joint">
		<hardwareInterface>hardware_interface/VelocityJointInterface</hardwareInterface>
	</joint>
  </transmission>
  <link
    name="right_rear_wheel_link">
    <inertial>
      <origin
        xyz="-3.7748E-15 0.00037977 4.3646E-15"
        rpy="0 0 0" />
      <mass
        value="2.856" />
      <inertia
        ixx="0.016151"
        ixy="-1.4136E-16"
        ixz="0"
        iyy="0.029635"
        iyz="1.1269E-30"
        izz="0.016151" />
    </inertial>
    <visual>
      <origin
        xyz="0 0 0"
        rpy="0 0 0" />
      <geometry>
        <mesh
          filename="package://scholar_description/meshes/right_rear_wheel_link.STL" />
      </geometry>
      <material
        name="">
        <color
          rgba="1 1 1 1" />
      </material>
    </visual>
    <collision>
      <origin
        xyz="0 0 0"
        rpy="1.5708 0 0" />
     <geometry>
	<cylinder length="${wheel_length}" radius="${wheel_radius}" />
     </geometry>
    </collision>
  </link>
  <joint
    name="right_rear_wheel_joint"
    type="continuous">
    <origin
      xyz="-0.199 -0.2395 0.06"
      rpy="0 0 0" />
    <parent
      link="base_link" />
    <child
      link="right_rear_wheel_link" />
    <axis
      xyz="0 1 0" />   
  </joint>


  <gazebo reference="right_rear_wheel_link">
        <mu1 value="1.0"/>
        <mu2 value="1.0"/>
	<kp value="10000000.0" />
	<kd value="1.0" />
	<fdir1 value="1 0 0"/>
  </gazebo>

  <transmission name="right_rear_wheel_trans" type="SimpleTransmission">
	<type>transmission_interface/SimpleTransmission</type>
	<actuator name="right_rear_wheel_motor">
		<mechanicalReduction>1</mechanicalReduction>
	</actuator>
	<joint name="right_rear_wheel_joint">
		<hardwareInterface>hardware_interface/VelocityJointInterface</hardwareInterface>
	</joint>
  </transmission>

  <gazebo>
    <plugin name="gazebo_ros_control" filename="libgazebo_ros_control.so">
      <robotNamespace>$(arg robot_namespace)</robotNamespace>
      <legacyModeNS>true</legacyModeNS>
    </plugin>
  </gazebo>

  <gazebo>
    <plugin name="imu_controller" filename="libhector_gazebo_ros_imu.so">
      <robotNamespace>$(arg robot_namespace)</robotNamespace>
      <updateRate>50.0</updateRate>
      <bodyName>imu_link</bodyName>
      <topicName>imu/data</topicName>
      <accelDrift>0.005 0.005 0.005</accelDrift>
      <accelGaussianNoise>0.005 0.005 0.005</accelGaussianNoise>
      <rateDrift>0.005 0.005 0.005 </rateDrift>
      <rateGaussianNoise>0.005 0.005 0.005 </rateGaussianNoise>
      <headingDrift>0.005</headingDrift>
      <headingGaussianNoise>0.005</headingGaussianNoise>
    </plugin>
  </gazebo>


 <gazebo reference="laser_frame">
      <turnGravityOff>true</turnGravityOff>
      <sensor type="ray" name="yplidar">
        <pose>0 0 0 0 0 0</pose>
        <visualize>false</visualize>
        <update_rate>50</update_rate>
        <ray>
          <scan>
            <horizontal>
              <samples>720</samples>
              <resolution>1</resolution>
              <min_angle>-1.4</min_angle>
              <max_angle>1.4</max_angle>
            </horizontal>
          </scan>
          <range>
            <min>0.1</min>
            <max>30</max>
            <resolution>0.01</resolution>
          </range>
          <noise>
            <type>gaussian</type>
            <mean>0.0</mean>
            <stddev>0.001</stddev>
          </noise>
        </ray>
        <plugin name="gazebo_ros_laser" filename="libgazebo_ros_laser.so">
          <topicName>/scan</topicName>
          <frameName>laser_frame</frameName>
          <robotNamespace>/</robotNamespace>
        </plugin>
      </sensor>
    </gazebo>


</robot>
