<?xml version="1.0" encoding="utf-8"?>

<robot name="scholar_base" xmlns:xacro="http://ros.org/wiki/xacro">

  <xacro:arg name="robot_namespace" default="/" />  
  <xacro:property name="wheel_length" value="0.07" />
  <xacro:property name="wheel_radius" value="0.1325" />


  <link
    name="base_link">
    <inertial>
      <origin
        xyz="-0.0030686 7.3376E-05 0.097156"
        rpy="0 0 0" />
      <mass
        value="12.503" />
      <inertia
        ixx="0.33952"
        ixy="0.00072408"
        ixz="0.0082636"
        iyy="0.53411"
        iyz="9.4623E-06"
        izz="0.70959" />
    </inertial>
    <visual>
      <origin
        xyz="0 0 0"
        rpy="0 0 0" />
      <geometry>
        <mesh
          filename="package://scholar_base_description/meshes/base_link.STL" />
      </geometry>
      <material
        name="">
        <color
          rgba="0.58824 0.58824 0.63137 1" />
      </material>
    </visual>
    <collision>
      <origin
        xyz="0 0 0"
        rpy="0 0 0" />
      <geometry>
        <mesh
          filename="package://scholar_base_description/meshes/base_link.STL" />
      </geometry>
    </collision>
  </link>
  <link
    name="left_front_wheel_link">
    <inertial>
      <origin
        xyz="1.0808E-09 -1.6734E-09 8.7966E-05"
        rpy="0 0 0" />
      <mass
        value="9.9258" />
      <inertia
        ixx="0.061339"
        ixy="1.6243E-11"
        ixz="1.921E-10"
        iyy="0.061339"
        iyz="-2.072E-10"
        izz="0.10764" />
    </inertial>
    <visual>
      <origin
        xyz="0 0 0"
        rpy="0 0 0" />
      <geometry>
        <mesh
          filename="package://scholar_base_description/meshes/left_front_wheel_link.STL" />
      </geometry>
      <material
        name="">
        <color
          rgba="0.29804 0.29804 0.29804 1" />
      </material>
    </visual>
    <collision>
      <origin
        xyz="0 0 0"
        rpy="0 0 0" />
      <geometry>
	<cylinder length="${wheel_length}" radius="${wheel_radius}" />
        <!--mesh
          filename="package://scholar_base_description/meshes/left_front_wheel_link.STL" /-->
      </geometry>
    </collision>
  </link>
  <joint
    name="left_front_wheel_joint"
    type="continuous">
    <origin
      xyz="0.199 0.2387 0.06"
      rpy="1.5708 0 0" />
    <parent
      link="base_link" />
    <child
      link="left_front_wheel_link" />
    <axis
      xyz="0 0 -1" />
  </joint>


  <gazebo reference="left_front_wheel_link">
        <mu1 value="1.0"/>
        <mu2 value="1.0"/>
	<kp value="10000000.0" />
	<kd value="1.0" />
	<fdir1 value="0 0 -1"/>
  </gazebo>

  <transmission name="left_front_wheel_trans" type="SimpleTransmission">
	<type>transmission_interface/SimpleTransmission</type>
	<actuator name="left_front_wheel_motor">
		<mechanicalReduction>1</mechanicalReduction>
	</actuator>
	<joint name="left_front_wheel_joint">
		<hardwareInterface>hardware_interface/VelocityJointInterface</hardwareInterface>
	</joint>
  </transmission>

  <link
    name="left_rear_wheel_link">
    <inertial>
      <origin
        xyz="1.0801E-09 -1.6734E-09 8.7966E-05"
        rpy="0 0 0" />
      <mass
        value="9.9258" />
      <inertia
        ixx="0.061339"
        ixy="1.6318E-11"
        ixz="1.9201E-10"
        iyy="0.061339"
        iyz="-2.072E-10"
        izz="0.10764" />
    </inertial>
    <visual>
      <origin
        xyz="0 0 0"
        rpy="0 0 0" />
      <geometry>
        <mesh
          filename="package://scholar_base_description/meshes/left_rear_wheel_link.STL" />
      </geometry>
      <material
        name="">
        <color
          rgba="0.29804 0.29804 0.29804 1" />
      </material>
    </visual>
    <collision>
      <origin
        xyz="0 0 0"
        rpy="0 0 0" />
      <geometry>
	<cylinder length="${wheel_length}" radius="${wheel_radius}" />
        <!--mesh
          filename="package://scholar_base_description/meshes/left_rear_wheel_link.STL" /-->
      </geometry>
    </collision>
  </link>
  <joint
    name="left_rear_wheel_joint"
    type="continuous">
    <origin
      xyz="-0.199 0.2387 0.06"
      rpy="1.5708 0 0" />
    <parent
      link="base_link" />
    <child
      link="left_rear_wheel_link" />
    <axis
      xyz="0 0 -1" />
    <!--mimic
      joint="left_front_wheel_joint"
      multiplier="1"
      offset="0" /-->
  </joint>


  <gazebo reference="left_rear_wheel_link">
        <mu1 value="1.0"/>
        <mu2 value="1.0"/>
	<kp value="10000000.0" />
	<kd value="1.0" />
	<fdir1 value="0 0 -1"/>
  </gazebo>

  <transmission name="left_rear_wheel_trans" type="SimpleTransmission">
	<type>transmission_interface/SimpleTransmission</type>
	<actuator name="left_rear_wheel_motor">
		<mechanicalReduction>1</mechanicalReduction>
	</actuator>
	<joint name="left_rear_wheel_joint">
		<hardwareInterface>hardware_interface/VelocityJointInterface</hardwareInterface>
	</joint>
  </transmission>

  <link
    name="right_front_wheel_link">
    <inertial>
      <origin
        xyz="-1.0802E-09 1.6735E-09 8.7966E-05"
        rpy="0 0 0" />
      <mass
        value="9.9258" />
      <inertia
        ixx="0.061339"
        ixy="1.6319E-11"
        ixz="-1.9201E-10"
        iyy="0.061339"
        iyz="2.0721E-10"
        izz="0.10764" />
    </inertial>
    <visual>
      <origin
        xyz="0 0 0"
        rpy="0 0 0" />
      <geometry>
        <mesh
          filename="package://scholar_base_description/meshes/right_front_wheel_link.STL" />
      </geometry>
      <material
        name="">
        <color
          rgba="0.29804 0.29804 0.29804 1" />
      </material>
    </visual>
    <collision>
      <origin
        xyz="0 0 0"
        rpy="0 0 0" />
      <geometry>
	<cylinder length="${wheel_length}" radius="${wheel_radius}" />
        <!--mesh
          filename="package://scholar_base_description/meshes/right_front_wheel_link.STL" /-->
      </geometry>
    </collision>
  </link>
  <joint
    name="right_front_wheel_joint"
    type="continuous">
    <origin
      xyz="0.199 -0.2387 0.06"
      rpy="-1.5708 0 0" />
    <parent
      link="base_link" />
    <child
      link="right_front_wheel_link" />
    <axis
      xyz="0 0 1" />
  </joint>

  <gazebo reference="right_front_wheel_link">
        <mu1 value="1.0"/>
        <mu2 value="1.0"/>
	<kp value="10000000.0" />
	<kd value="1.0" />
	<fdir1 value="0 0 1"/>
  </gazebo>

  <transmission name="right_front_wheel_trans" type="SimpleTransmission">
	<type>transmission_interface/SimpleTransmission</type>
	<actuator name="right_front_wheel_motor">
		<mechanicalReduction>1</mechanicalReduction>
	</actuator>
	<joint name="right_front_wheel_joint">
		<hardwareInterface>hardware_interface/VelocityJointInterface</hardwareInterface>
	</joint>
  </transmission>

  <link
    name="right_rear_wheel_link">
    <inertial>
      <origin
        xyz="-1.0809E-09 1.6733E-09 8.7966E-05"
        rpy="0 0 0" />
      <mass
        value="9.9258" />
      <inertia
        ixx="0.061339"
        ixy="1.6149E-11"
        ixz="-1.9212E-10"
        iyy="0.061339"
        iyz="2.0719E-10"
        izz="0.10764" />
    </inertial>
    <visual>
      <origin
        xyz="0 0 0"
        rpy="0 0 0" />
      <geometry>
        <mesh
          filename="package://scholar_base_description/meshes/right_rear_wheel_link.STL" />
      </geometry>
      <material
        name="">
        <color
          rgba="0.29804 0.29804 0.29804 1" />
      </material>
    </visual>
    <collision>
      <origin
        xyz="0 0 0"
        rpy="0 0 0" />
      <geometry>
	<cylinder length="${wheel_length}" radius="${wheel_radius}" />
        <!--mesh
          filename="package://scholar_base_description/meshes/right_rear_wheel_link.STL" /-->
      </geometry>
    </collision>
  </link>
  <joint
    name="right_rear_wheel_joint"
    type="continuous">
    <origin
      xyz="-0.199 -0.2387 0.06"
      rpy="-1.5708 0 0" />
    <parent
      link="base_link" />
    <child
      link="right_rear_wheel_link" />
    <axis
      xyz="0 0 1" />
    <!--mimic
      joint="right_front_wheel_joint"
      multiplier="1"
      offset="0" /-->
  </joint>


  <gazebo reference="right_rear_wheel_link">
        <mu1 value="1.0"/>
        <mu2 value="1.0"/>
	<kp value="10000000.0" />
	<kd value="1.0" />
	<fdir1 value="0 0 1"/>
  </gazebo>

  <transmission name="right_rear_wheel_trans" type="SimpleTransmission">
	<type>transmission_interface/SimpleTransmission</type>
	<actuator name="right_rear_wheel_motor">
		<mechanicalReduction>1</mechanicalReduction>
	</actuator>
	<joint name="right_rear_wheel_joint">
		<hardwareInterface>hardware_interface/VelocityJointInterface</hardwareInterface>
	</joint>
  </transmission>


  <link
    name="imu_link">  
  </link>
  <joint
    name="imu_joint"
    type="fixed">
    <origin
      xyz="0.2055 -0.008 0.012"
      rpy="0 0 0" />
    <parent
      link="base_link" />
    <child
      link="imu_link" />
    <axis
      xyz="0 0 0" />
  </joint>
  <link
    name="top_plate_link">
  </link>
  <joint
    name="top_plate_joint"
    type="fixed">
    <origin
      xyz="0 0 0.23019"
      rpy="0 0 0" />
    <parent
      link="base_link" />
    <child
      link="top_plate_link" />
    <axis
      xyz="0 0 0" />
  </joint>


  <gazebo>
    <plugin name="gazebo_ros_control" filename="libgazebo_ros_control.so">
      <robotNamespace>$(arg robot_namespace)</robotNamespace>
      <legacyModeNS>true</legacyModeNS>
    </plugin>
  </gazebo>

  <gazebo>
    <plugin name="imu_controller" filename="libhector_gazebo_ros_imu.so">
      <robotNamespace>$(arg robot_namespace)</robotNamespace>
      <updateRate>50.0</updateRate>
      <bodyName>imu_link</bodyName>
      <topicName>imu/data</topicName>
      <accelDrift>0.005 0.005 0.005</accelDrift>
      <accelGaussianNoise>0.005 0.005 0.005</accelGaussianNoise>
      <rateDrift>0.005 0.005 0.005 </rateDrift>
      <rateGaussianNoise>0.005 0.005 0.005 </rateGaussianNoise>
      <headingDrift>0.005</headingDrift>
      <headingGaussianNoise>0.005</headingGaussianNoise>
    </plugin>
  </gazebo>

</robot>
